2019-07-10 21:47:07,131 - base.py:[28] - [INFO] - _open is accessing address http:192.168.0.91 at line[46]
2019-07-10 21:47:07,131 - base.py:[32] - [INFO] - http:192.168.0.91 loading successed!
2019-07-10 21:47:07,166 - base.py:[42] - [INFO] - The page of <page_obj.LoginPage.login object at 0x000001F3D7BB8198> had already find the element ('xpath', "//*[@id='user']")
2019-07-10 21:47:07,234 - base.py:[64] - [INFO] - inputValue:[('xpath', "//*[@id='user']")] is receiveing value [admin]
2019-07-10 21:47:07,255 - base.py:[42] - [INFO] - The page of <page_obj.LoginPage.login object at 0x000001F3D7BB8198> had already find the element ('xpath', "//*[@id='password']")
2019-07-10 21:47:07,315 - base.py:[64] - [INFO] - inputValue:[('xpath', "//*[@id='password']")] is receiveing value [admin2003]
2019-07-10 21:47:07,335 - base.py:[42] - [INFO] - The page of <page_obj.LoginPage.login object at 0x000001F3D7BB8198> had already find the element ('xpath', "//*[@id='submit']")
2019-07-10 21:47:11,539 - base.py:[42] - [INFO] - The page of test_01previewPNGfiles (g_preview_sta.PreviewTest) had already find the element ('xpath', "//*[@id='searchbox']")
2019-07-10 21:47:12,152 - base.py:[42] - [INFO] - The page of test_01previewPNGfiles (g_preview_sta.PreviewTest) had already find the element ('xpath', "//*[@id='searchbox']")
2019-07-10 21:47:23,541 - base.py:[39] - [ERROR] - finding element timeout!, details
Traceback (most recent call last):
  File "E:\Security_retail_test_project\retail\test_case\page_obj\base.py", line 37, in findElement
    WebDriverWait(self.driver, 10).until(EC.visibility_of_element_located(loc))
  File "C:\Python36\lib\site-packages\selenium\webdriver\support\wait.py", line 80, in until
    raise TimeoutException(message, screen, stacktrace)
selenium.common.exceptions.TimeoutException: Message: 

2019-07-10 21:47:24,389 - base.py:[28] - [INFO] - _open is accessing address http:192.168.0.91 at line[46]
2019-07-10 21:47:24,389 - base.py:[32] - [INFO] - http:192.168.0.91 loading successed!
2019-07-10 21:47:34,958 - base.py:[39] - [ERROR] - finding element timeout!, details
Traceback (most recent call last):
  File "E:\Security_retail_test_project\retail\test_case\page_obj\base.py", line 37, in findElement
    WebDriverWait(self.driver, 10).until(EC.visibility_of_element_located(loc))
  File "C:\Python36\lib\site-packages\selenium\webdriver\support\wait.py", line 80, in until
    raise TimeoutException(message, screen, stacktrace)
selenium.common.exceptions.TimeoutException: Message: 

2019-07-10 21:47:41,181 - base.py:[28] - [INFO] - _open is accessing address http:192.168.0.91 at line[46]
2019-07-10 21:47:41,181 - base.py:[32] - [INFO] - http:192.168.0.91 loading successed!
2019-07-10 21:47:41,211 - base.py:[42] - [INFO] - The page of <page_obj.LoginPage.login object at 0x000001F3D7BBD080> had already find the element ('xpath', "//*[@id='user']")
2019-07-10 21:47:41,269 - base.py:[64] - [INFO] - inputValue:[('xpath', "//*[@id='user']")] is receiveing value [admin]
2019-07-10 21:47:41,291 - base.py:[42] - [INFO] - The page of <page_obj.LoginPage.login object at 0x000001F3D7BBD080> had already find the element ('xpath', "//*[@id='password']")
2019-07-10 21:47:41,354 - base.py:[64] - [INFO] - inputValue:[('xpath', "//*[@id='password']")] is receiveing value [admin2003]
2019-07-10 21:47:41,375 - base.py:[42] - [INFO] - The page of <page_obj.LoginPage.login object at 0x000001F3D7BBD080> had already find the element ('xpath', "//*[@id='submit']")
2019-07-10 21:47:43,617 - base.py:[42] - [INFO] - The page of test_01searchfiles (h_search_sta.SearchTest) had already find the element ('xpath', "//*[@id='searchbox']")
2019-07-10 21:47:44,221 - base.py:[42] - [INFO] - The page of test_01searchfiles (h_search_sta.SearchTest) had already find the element ('xpath', "//*[@id='searchbox']")
2019-07-10 21:47:46,727 - base.py:[42] - [INFO] - The page of <page_obj.LoginPage.login object at 0x000001F3D7BBD080> had already find the element ('xpath', "//*[@id='expand']")
2019-07-10 21:47:48,800 - base.py:[42] - [INFO] - The page of <page_obj.LoginPage.login object at 0x000001F3D7BBD080> had already find the element ('xpath', "//*[@id='expanddiv']/ul/li[2]/a")
2019-07-10 21:47:52,290 - base.py:[28] - [INFO] - _open is accessing address http:192.168.0.91 at line[46]
2019-07-10 21:47:52,290 - base.py:[32] - [INFO] - http:192.168.0.91 loading successed!
2019-07-10 21:47:52,310 - base.py:[42] - [INFO] - The page of <page_obj.LoginPage.login object at 0x000001F3D7BBD390> had already find the element ('xpath', "//*[@id='user']")
2019-07-10 21:47:52,364 - base.py:[64] - [INFO] - inputValue:[('xpath', "//*[@id='user']")] is receiveing value [admin]
2019-07-10 21:47:52,382 - base.py:[42] - [INFO] - The page of <page_obj.LoginPage.login object at 0x000001F3D7BBD390> had already find the element ('xpath', "//*[@id='password']")
2019-07-10 21:47:52,442 - base.py:[64] - [INFO] - inputValue:[('xpath', "//*[@id='password']")] is receiveing value [admin2003]
2019-07-10 21:47:52,462 - base.py:[42] - [INFO] - The page of <page_obj.LoginPage.login object at 0x000001F3D7BBD390> had already find the element ('xpath', "//*[@id='submit']")
2019-07-10 21:47:54,225 - base.py:[42] - [INFO] - The page of test_02searchfolder (h_search_sta.SearchTest) had already find the element ('xpath', "//*[@id='searchbox']")
2019-07-10 21:47:54,871 - base.py:[42] - [INFO] - The page of test_02searchfolder (h_search_sta.SearchTest) had already find the element ('xpath', "//*[@id='searchbox']")
2019-07-10 21:47:58,360 - base.py:[42] - [INFO] - The page of <page_obj.LoginPage.login object at 0x000001F3D7BBD390> had already find the element ('xpath', "//*[@id='expand']")
2019-07-10 21:48:00,487 - base.py:[42] - [INFO] - The page of <page_obj.LoginPage.login object at 0x000001F3D7BBD390> had already find the element ('xpath', "//*[@id='expanddiv']/ul/li[2]/a")
2019-07-10 21:48:06,482 - base.py:[28] - [INFO] - _open is accessing address http:192.168.0.91 at line[46]
2019-07-10 21:48:06,482 - base.py:[32] - [INFO] - http:192.168.0.91 loading successed!
2019-07-10 21:48:06,508 - base.py:[42] - [INFO] - The page of <page_obj.LoginPage.login object at 0x000001F3D7BB8C88> had already find the element ('xpath', "//*[@id='user']")
2019-07-10 21:48:06,569 - base.py:[64] - [INFO] - inputValue:[('xpath', "//*[@id='user']")] is receiveing value [admin]
2019-07-10 21:48:06,591 - base.py:[42] - [INFO] - The page of <page_obj.LoginPage.login object at 0x000001F3D7BB8C88> had already find the element ('xpath', "//*[@id='password']")
2019-07-10 21:48:06,652 - base.py:[64] - [INFO] - inputValue:[('xpath', "//*[@id='password']")] is receiveing value [admin2003]
2019-07-10 21:48:06,674 - base.py:[42] - [INFO] - The page of <page_obj.LoginPage.login object at 0x000001F3D7BB8C88> had already find the element ('xpath', "//*[@id='submit']")
2019-07-10 21:48:38,450 - base.py:[39] - [ERROR] - finding element timeout!, details
Traceback (most recent call last):
  File "E:\Security_retail_test_project\retail\test_case\page_obj\base.py", line 37, in findElement
    WebDriverWait(self.driver, 10).until(EC.visibility_of_element_located(loc))
  File "C:\Python36\lib\site-packages\selenium\webdriver\support\wait.py", line 80, in until
    raise TimeoutException(message, screen, stacktrace)
selenium.common.exceptions.TimeoutException: Message: 

2019-07-10 21:48:39,280 - base.py:[28] - [INFO] - _open is accessing address http:192.168.0.91 at line[46]
2019-07-10 21:48:39,281 - base.py:[32] - [INFO] - http:192.168.0.91 loading successed!
2019-07-10 21:48:49,835 - base.py:[39] - [ERROR] - finding element timeout!, details
Traceback (most recent call last):
  File "E:\Security_retail_test_project\retail\test_case\page_obj\base.py", line 37, in findElement
    WebDriverWait(self.driver, 10).until(EC.visibility_of_element_located(loc))
  File "C:\Python36\lib\site-packages\selenium\webdriver\support\wait.py", line 80, in until
    raise TimeoutException(message, screen, stacktrace)
selenium.common.exceptions.TimeoutException: Message: 

2019-07-10 21:48:50,639 - base.py:[28] - [INFO] - _open is accessing address http:192.168.0.91 at line[46]
2019-07-10 21:48:50,639 - base.py:[32] - [INFO] - http:192.168.0.91 loading successed!
2019-07-10 21:49:01,157 - base.py:[39] - [ERROR] - finding element timeout!, details
Traceback (most recent call last):
  File "E:\Security_retail_test_project\retail\test_case\page_obj\base.py", line 37, in findElement
    WebDriverWait(self.driver, 10).until(EC.visibility_of_element_located(loc))
  File "C:\Python36\lib\site-packages\selenium\webdriver\support\wait.py", line 80, in until
    raise TimeoutException(message, screen, stacktrace)
selenium.common.exceptions.TimeoutException: Message: 

2019-07-10 21:49:01,942 - base.py:[28] - [INFO] - _open is accessing address http:192.168.0.91 at line[46]
2019-07-10 21:49:01,942 - base.py:[32] - [INFO] - http:192.168.0.91 loading successed!
2019-07-10 21:49:12,500 - base.py:[39] - [ERROR] - finding element timeout!, details
Traceback (most recent call last):
  File "E:\Security_retail_test_project\retail\test_case\page_obj\base.py", line 37, in findElement
    WebDriverWait(self.driver, 10).until(EC.visibility_of_element_located(loc))
  File "C:\Python36\lib\site-packages\selenium\webdriver\support\wait.py", line 80, in until
    raise TimeoutException(message, screen, stacktrace)
selenium.common.exceptions.TimeoutException: Message: 

2019-07-10 21:49:13,341 - base.py:[28] - [INFO] - _open is accessing address http:192.168.0.91 at line[46]
2019-07-10 21:49:13,341 - base.py:[32] - [INFO] - http:192.168.0.91 loading successed!
2019-07-10 21:49:23,906 - base.py:[39] - [ERROR] - finding element timeout!, details
Traceback (most recent call last):
  File "E:\Security_retail_test_project\retail\test_case\page_obj\base.py", line 37, in findElement
    WebDriverWait(self.driver, 10).until(EC.visibility_of_element_located(loc))
  File "C:\Python36\lib\site-packages\selenium\webdriver\support\wait.py", line 80, in until
    raise TimeoutException(message, screen, stacktrace)
selenium.common.exceptions.TimeoutException: Message: 

2019-07-10 21:49:29,725 - base.py:[28] - [INFO] - _open is accessing address http:192.168.0.91 at line[46]
2019-07-10 21:49:29,725 - base.py:[32] - [INFO] - http:192.168.0.91 loading successed!
2019-07-10 21:49:29,751 - base.py:[42] - [INFO] - The page of <page_obj.LoginPage.login object at 0x000001F3D7BD1240> had already find the element ('xpath', "//*[@id='user']")
2019-07-10 21:49:29,812 - base.py:[64] - [INFO] - inputValue:[('xpath', "//*[@id='user']")] is receiveing value [admin]
2019-07-10 21:49:29,832 - base.py:[42] - [INFO] - The page of <page_obj.LoginPage.login object at 0x000001F3D7BD1240> had already find the element ('xpath', "//*[@id='password']")
2019-07-10 21:49:29,892 - base.py:[64] - [INFO] - inputValue:[('xpath', "//*[@id='password']")] is receiveing value [admin2003]
2019-07-10 21:49:29,912 - base.py:[42] - [INFO] - The page of <page_obj.LoginPage.login object at 0x000001F3D7BD1240> had already find the element ('xpath', "//*[@id='submit']")
2019-07-10 21:50:01,671 - base.py:[39] - [ERROR] - finding element timeout!, details
Traceback (most recent call last):
  File "E:\Security_retail_test_project\retail\test_case\page_obj\base.py", line 37, in findElement
    WebDriverWait(self.driver, 10).until(EC.visibility_of_element_located(loc))
  File "C:\Python36\lib\site-packages\selenium\webdriver\support\wait.py", line 80, in until
    raise TimeoutException(message, screen, stacktrace)
selenium.common.exceptions.TimeoutException: Message: 

2019-07-10 21:50:07,415 - base.py:[28] - [INFO] - _open is accessing address http:192.168.0.91 at line[46]
2019-07-10 21:50:07,415 - base.py:[32] - [INFO] - http:192.168.0.91 loading successed!
2019-07-10 21:50:07,444 - base.py:[42] - [INFO] - The page of <page_obj.LoginPage.login object at 0x000001F3D7BD1EB8> had already find the element ('xpath', "//*[@id='user']")
2019-07-10 21:50:07,502 - base.py:[64] - [INFO] - inputValue:[('xpath', "//*[@id='user']")] is receiveing value [admin]
2019-07-10 21:50:07,523 - base.py:[42] - [INFO] - The page of <page_obj.LoginPage.login object at 0x000001F3D7BD1EB8> had already find the element ('xpath', "//*[@id='password']")
2019-07-10 21:50:07,582 - base.py:[64] - [INFO] - inputValue:[('xpath', "//*[@id='password']")] is receiveing value [admin2003]
2019-07-10 21:50:07,603 - base.py:[42] - [INFO] - The page of <page_obj.LoginPage.login object at 0x000001F3D7BD1EB8> had already find the element ('xpath', "//*[@id='submit']")
2019-07-10 21:50:39,268 - base.py:[39] - [ERROR] - finding element timeout!, details
Traceback (most recent call last):
  File "E:\Security_retail_test_project\retail\test_case\page_obj\base.py", line 37, in findElement
    WebDriverWait(self.driver, 10).until(EC.visibility_of_element_located(loc))
  File "C:\Python36\lib\site-packages\selenium\webdriver\support\wait.py", line 80, in until
    raise TimeoutException(message, screen, stacktrace)
selenium.common.exceptions.TimeoutException: Message: 

2019-07-10 21:52:38,441 - base.py:[28] - [INFO] - _open is accessing address http:192.168.0.91 at line[46]
2019-07-10 21:52:38,441 - base.py:[32] - [INFO] - http:192.168.0.91 loading successed!
2019-07-10 21:52:38,472 - base.py:[42] - [INFO] - The page of <page_obj.LoginPage.login object at 0x000001F3D7BF9B70> had already find the element ('xpath', "//*[@id='user']")
2019-07-10 21:52:38,536 - base.py:[64] - [INFO] - inputValue:[('xpath', "//*[@id='user']")] is receiveing value [admin]
2019-07-10 21:52:38,558 - base.py:[42] - [INFO] - The page of <page_obj.LoginPage.login object at 0x000001F3D7BF9B70> had already find the element ('xpath', "//*[@id='password']")
2019-07-10 21:52:38,621 - base.py:[64] - [INFO] - inputValue:[('xpath', "//*[@id='password']")] is receiveing value [admin2003]
2019-07-10 21:52:38,642 - base.py:[42] - [INFO] - The page of <page_obj.LoginPage.login object at 0x000001F3D7BF9B70> had already find the element ('xpath', "//*[@id='submit']")
2019-07-10 21:53:12,385 - base.py:[39] - [ERROR] - finding element timeout!, details
Traceback (most recent call last):
  File "E:\Security_retail_test_project\retail\test_case\page_obj\base.py", line 37, in findElement
    WebDriverWait(self.driver, 10).until(EC.visibility_of_element_located(loc))
  File "C:\Python36\lib\site-packages\selenium\webdriver\support\wait.py", line 80, in until
    raise TimeoutException(message, screen, stacktrace)
selenium.common.exceptions.TimeoutException: Message: 

2019-07-10 21:53:13,247 - base.py:[28] - [INFO] - _open is accessing address http:192.168.0.91 at line[46]
2019-07-10 21:53:13,247 - base.py:[32] - [INFO] - http:192.168.0.91 loading successed!
2019-07-10 21:53:23,799 - base.py:[39] - [ERROR] - finding element timeout!, details
Traceback (most recent call last):
  File "E:\Security_retail_test_project\retail\test_case\page_obj\base.py", line 37, in findElement
    WebDriverWait(self.driver, 10).until(EC.visibility_of_element_located(loc))
  File "C:\Python36\lib\site-packages\selenium\webdriver\support\wait.py", line 80, in until
    raise TimeoutException(message, screen, stacktrace)
selenium.common.exceptions.TimeoutException: Message: 

2019-07-10 21:53:29,640 - base.py:[28] - [INFO] - _open is accessing address http:192.168.0.91 at line[46]
2019-07-10 21:53:29,640 - base.py:[32] - [INFO] - http:192.168.0.91 loading successed!
2019-07-10 21:53:29,665 - base.py:[42] - [INFO] - The page of <page_obj.LoginPage.login object at 0x000001F3D7BF9D30> had already find the element ('xpath', "//*[@id='user']")
2019-07-10 21:53:29,723 - base.py:[64] - [INFO] - inputValue:[('xpath', "//*[@id='user']")] is receiveing value [admin]
2019-07-10 21:53:29,745 - base.py:[42] - [INFO] - The page of <page_obj.LoginPage.login object at 0x000001F3D7BF9D30> had already find the element ('xpath', "//*[@id='password']")
2019-07-10 21:53:29,805 - base.py:[64] - [INFO] - inputValue:[('xpath', "//*[@id='password']")] is receiveing value [admin2003]
2019-07-10 21:53:29,825 - base.py:[42] - [INFO] - The page of <page_obj.LoginPage.login object at 0x000001F3D7BF9D30> had already find the element ('xpath', "//*[@id='submit']")
2019-07-10 21:53:43,534 - base.py:[39] - [ERROR] - finding element timeout!, details
Traceback (most recent call last):
  File "E:\Security_retail_test_project\retail\test_case\page_obj\base.py", line 37, in findElement
    WebDriverWait(self.driver, 10).until(EC.visibility_of_element_located(loc))
  File "C:\Python36\lib\site-packages\selenium\webdriver\support\wait.py", line 80, in until
    raise TimeoutException(message, screen, stacktrace)
selenium.common.exceptions.TimeoutException: Message: 

2019-07-10 21:53:44,362 - base.py:[28] - [INFO] - _open is accessing address http:192.168.0.91 at line[46]
2019-07-10 21:53:44,362 - base.py:[32] - [INFO] - http:192.168.0.91 loading successed!
2019-07-10 21:53:54,899 - base.py:[39] - [ERROR] - finding element timeout!, details
Traceback (most recent call last):
  File "E:\Security_retail_test_project\retail\test_case\page_obj\base.py", line 37, in findElement
    WebDriverWait(self.driver, 10).until(EC.visibility_of_element_located(loc))
  File "C:\Python36\lib\site-packages\selenium\webdriver\support\wait.py", line 80, in until
    raise TimeoutException(message, screen, stacktrace)
selenium.common.exceptions.TimeoutException: Message: 

2019-07-10 21:53:55,761 - base.py:[28] - [INFO] - _open is accessing address http:192.168.0.91 at line[46]
2019-07-10 21:53:55,762 - base.py:[32] - [INFO] - http:192.168.0.91 loading successed!
2019-07-10 21:54:06,344 - base.py:[39] - [ERROR] - finding element timeout!, details
Traceback (most recent call last):
  File "E:\Security_retail_test_project\retail\test_case\page_obj\base.py", line 37, in findElement
    WebDriverWait(self.driver, 10).until(EC.visibility_of_element_located(loc))
  File "C:\Python36\lib\site-packages\selenium\webdriver\support\wait.py", line 80, in until
    raise TimeoutException(message, screen, stacktrace)
selenium.common.exceptions.TimeoutException: Message: 

2019-07-10 21:54:07,165 - base.py:[28] - [INFO] - _open is accessing address http:192.168.0.91 at line[46]
2019-07-10 21:54:07,166 - base.py:[32] - [INFO] - http:192.168.0.91 loading successed!
2019-07-10 21:54:17,695 - base.py:[39] - [ERROR] - finding element timeout!, details
Traceback (most recent call last):
  File "E:\Security_retail_test_project\retail\test_case\page_obj\base.py", line 37, in findElement
    WebDriverWait(self.driver, 10).until(EC.visibility_of_element_located(loc))
  File "C:\Python36\lib\site-packages\selenium\webdriver\support\wait.py", line 80, in until
    raise TimeoutException(message, screen, stacktrace)
selenium.common.exceptions.TimeoutException: Message: 

